Workbook

Sheet Cover
B2: EMEA Banking Sector - NIM Sensitivity Model
B4: Author: Samrudhi Shevare
B5: Coverage: Barclays, BNP Paribas, Deutsche Bank
B6: Source: Company annual reports, Yahoo Finance (yfinance)
B8: Contents | C8: Description
B9: Model Sheets
B10: =HYPERLINK("#Assumptions!A1","Assumptions") -> Assumptions | C10: Scenario toggle, central bank rates, bank-level inputs (β, lag, tax)
B11: =HYPERLINK("#Calc_Barclays!A1","Calc_Barclays") -> Calc_Barclays | C11: Barclays FY24A vs FY25E P&L and ratios (£bn)
B12: =HYPERLINK("#Calc_BNP!A1","Calc_BNP") -> Calc_BNP | C12: BNP Paribas FY24A vs FY25E P&L and ratios (€bn)
B13: =HYPERLINK("#Calc_Deutsche!A1","Calc_Deutsche") -> Calc_Deutsche | C13: Deutsche Bank FY24A vs FY25E P&L and ratios (€bn)
B14: =HYPERLINK("#Sensitivity!A1","Sensitivity") -> Sensitivity | C14: ROE grids: ΔRate × deposit β for all three banks, with heatmap
B15: =HYPERLINK("#Scenarios!A1","Scenarios") -> Scenarios | C15: Bear / Base / Bull FY25E outputs side by side
B16: =HYPERLINK("#Chartbook!A1","Chartbook") -> Chartbook | C16: Four charts: Net Income by scenario, historical ROE/NIM, FY24 C/I
B18: Source Data
B19: =HYPERLINK("#ratios_summary!A1","ratios_summary") -> ratios_summary | C19: Historical NIM / ROE / ROA / C/I / Net Income by bank & year
B20: =HYPERLINK("#sensitivity_results!A1","sensitivity_results") -> sensitivity_results | C20: Prior Python sensitivity output (reference)
B21: =HYPERLINK("#income_Barclays!A1","income_Barclays") -> income_Barclays | C21: Barclays income statement FY2021 - FY2025 (raw £)
B22: =HYPERLINK("#income_BNP_Paribas!A1","income_BNP_Paribas") -> income_BNP_Paribas | C22: BNP Paribas income statement FY2021 - FY2025 (raw €)
B23: =HYPERLINK("#income_Deutsche_Bank!A1","income_Deutsche_Bank") -> income_Deutsche_Bank | C23: Deutsche Bank income statement FY2022 - FY2025 (raw €)
B24: =HYPERLINK("#balance_Barclays!A1","balance_Barclays") -> balance_Barclays | C24: Barclays balance sheet FY2022 - FY2025 (raw £)
B25: =HYPERLINK("#balance_BNP_Paribas!A1","balance_BNP_Paribas") -> balance_BNP_Paribas | C25: BNP Paribas balance sheet FY2021 - FY2025 (raw €)
B26: =HYPERLINK("#balance_Deutsche_Bank!A1","balance_Deutsche_Bank") -> balance_Deutsche_Bank | C26: Deutsche Bank balance sheet FY2022 - FY2025 (raw €)
B27: =HYPERLINK("#bank_metrics!A1","bank_metrics") -> bank_metrics | C27: Current price, market cap, P/B, P/E, ROE/ROA snapshot
B28: =HYPERLINK("#bank_prices!A1","bank_prices") -> bank_prices | C28: Daily share price history (Barclays, BNP, Deutsche)

Sheet Assumptions
A1: EMEA Banking NIM Model - Assumptions
A3: Scenario: | D3: Base | E3: ← change to Bear / Base / Bull
A5: Central Bank Rates | B5: Bear | C5: Base | D5: Bull | E5: Selected | F5: FY2024 Actual | G5: Δ Rate
A6: ECB Rate (eurozone) | B6: 0.0175 | C6: 0.0225 | D6: 0.0275 | E6: =CHOOSE(MATCH($D$3,{"Bear","Base","Bull"},0),B6,C6,D6) -> 0.0225 | F6: 0.0315 | G6: =E6-F6 -> -0.009
A7: BoE Rate (UK) | B7: 0.0375 | C7: 0.0425 | D7: 0.0475 | E7: =CHOOSE(MATCH($D$3,{"Bear","Base","Bull"},0),B7,C7,D7) -> 0.0425 | F7: 0.05 | G7: =E7-F7 -> -0.0075
A9: Bank Inputs | B9: Barclays | C9: BNP Paribas | D9: Deutsche Bank | E9: Central Bank
A10: Deposit Beta | B10: 0.42 | C10: 0.38 | D10: 0.32
A11: Repricing Lag | B11: 0.65 | C11: 0.6 | D11: 0.7
A12: Cost Inflation | B12: 0.02 | C12: 0.02 | D12: 0.02
A13: Fee Growth | B13: 0.02 | C13: 0.02 | D13: 0.02
A14: Tax Rate | B14: 0.22 | C14: 0.265 | D14: 0.25
A15: Applicable Rate Ref | B15: BoE | C15: ECB | D15: ECB
A17: Color key: | B17: Hardcoded input | C17: Formula | D17: Cross-sheet link | E17: Key toggle

Sheet Calc_Barclays
A1: Calc_Barclays - NIM-driven P&L (£bn)
A2: All figures in £ billions unless noted. Source figures divided by 1,000,000,000.
B4: FY2024A | C4: FY2025E
A6: Income Statement
A7: Net Interest Income | B7: =income_Barclays!C8/1000000000 -> 12.936 | C7: =C32*C35 -> 8.6432838
A8: Non-Interest Income (Fees) | B8: =B9-B7 -> 13.294 | C8: =B8*(1+Assumptions!B13) -> 13.55988
A9: Total Revenue | B9: =income_Barclays!C40/1000000000 -> 26.23 | C9: =C7+C8 -> 22.203164
A10: Operating Expense | B10: =income_Barclays!C32/1000000000 -> 15.964 | C10: =B10*(1+Assumptions!B12) -> 16.28328
A11: Pretax Income | B11: =income_Barclays!C26/1000000000 -> 8.108 | C11: =C9-C10 -> 5.9198838
A12: Tax Provision | B12: =income_Barclays!C25/1000000000 -> 1.752 | C12: =C11*Assumptions!B14 -> 1.3023744
A13: Net Income | B13: =income_Barclays!C20/1000000000 -> 6.307 | C13: =C11-C12 -> 4.6175094
A15: Balance Sheet
A16: Total Assets | B16: =balance_Barclays!C25/1000000000 -> 1518.202 | C16: =C35 -> 1518.202
A17: Common Stock Equity | B17: =balance_Barclays!C9/1000000000 -> 71.821 | C17: =B17+C13 -> 76.438509
A19: Key Ratios
A20: NIM (NII / Total Assets) | B20: =B7/B16 -> 0.0085206053 | C20: =C7/C16 -> 0.0056931053
A21: Effective Tax Rate | B21: =B12/B11 -> 0.21608288 | C21: =Assumptions!B14 -> 0.22
A22: ROE (Net Income / Equity) | B22: =B13/B17 -> 0.087815541 | C22: =C13/((B17+C17)/2) -> 0.062289555
A23: Cost-to-Income | B23: =B10/B9 -> 0.60861609 | C23: =C10/C9 -> 0.73337656
A25: FY25E Drivers
A26: Applicable CB rate (BoE) | C26: =Assumptions!E7 -> 0.0425
A27: FY24 CB rate | C27: =Assumptions!F7 -> 0.05
A28: Δ Rate | C28: =C26-C27 -> -0.0075
A29: Deposit Beta | C29: =Assumptions!B10 -> 0.42
A30: Repricing Lag | C30: =Assumptions!B11 -> 0.65
A31: NIM change = ΔRate × (1 − β) × Lag | C31: =C28*(1-C29)*C30 -> -0.0028275
A32: NIM FY25E | B32: =B20 -> 0.0085206053 | C32: =B20+C31 -> 0.0056931053
A34: FY25E P&L
A35: Total Assets (held flat) | C35: =B16 -> 1518.202

Sheet Calc_BNP
A1: Calc_BNP Paribas - NIM-driven P&L (€bn)
A2: All figures in € billions. Source figures divided by 1,000,000,000.
B4: FY2024A | C4: FY2025E
A6: Income Statement
A7: Net Interest Income | B7: =income_BNP_Paribas!C8/1000000000 -> 19.524 | C7: =C32*C35 -> 10.467968
A8: Non-Interest Income (Fees) | B8: =B9-B7 -> 46.346 | C8: =B8*(1+Assumptions!C13) -> 47.27292
A9: Total Revenue | B9: =income_BNP_Paribas!C41/1000000000 -> 65.87 | C9: =C7+C8 -> 57.740888
A10: Operating Expense | B10: =income_BNP_Paribas!C33/1000000000 -> 47.403 | C10: =B10*(1+Assumptions!C12) -> 48.35106
A11: Pretax Income | B11: =income_BNP_Paribas!C26/1000000000 -> 16.188 | C11: =C9-C10 -> 9.389828
A12: Tax Provision | B12: =income_BNP_Paribas!C25/1000000000 -> 4.001 | C12: =C11*Assumptions!C14 -> 2.4883044
A13: Net Income | B13: =income_BNP_Paribas!C20/1000000000 -> 11.688 | C13: =C11-C12 -> 6.9015236
A15: Balance Sheet
A16: Total Assets | B16: =balance_BNP_Paribas!C25/1000000000 -> 2704.908 | C16: =C35 -> 2704.908
A17: Common Stock Equity | B17: =balance_BNP_Paribas!C10/1000000000 -> 128.137 | C17: =B17+C13 -> 135.03852
A19: Key Ratios
A20: NIM (NII / Total Assets) | B20: =B7/B16 -> 0.0072179904 | C20: =C7/C16 -> 0.0038699904
A21: Effective Tax Rate | B21: =B12/B11 -> 0.24715839 | C21: =Assumptions!C14 -> 0.265
A22: ROE (Net Income / Equity) | B22: =B13/B17 -> 0.091214872 | C22: =C13/((B17+C17)/2) -> 0.052448066
A23: Cost-to-Income | B23: =B10/B9 -> 0.71964475 | C23: =C10/C9 -> 0.83737992
A25: FY25E Drivers
A26: Applicable CB rate (ECB) | C26: =Assumptions!E6 -> 0.0225
A27: FY24 CB rate | C27: =Assumptions!F6 -> 0.0315
A28: Δ Rate | C28: =C26-C27 -> -0.009
A29: Deposit Beta | C29: =Assumptions!C10 -> 0.38
A30: Repricing Lag | C30: =Assumptions!C11 -> 0.6
A31: NIM change = ΔRate × (1 − β) × Lag | C31: =C28*(1-C29)*C30 -> -0.003348
A32: NIM FY25E | B32: =B20 -> 0.0072179904 | C32: =B20+C31 -> 0.0038699904
A34: FY25E P&L
A35: Total Assets (held flat) | C35: =B16 -> 2704.908

Sheet Calc_Deutsche
A1: Calc_Deutsche Bank - NIM-driven P&L (€bn)
A2: All figures in € billions. OpEx = SG&A + Other Non Interest Expense. Source figures ÷ 1,000,000,000.
B4: FY2024A | C4: FY2025E
A6: Income Statement
A7: Net Interest Income | B7: =income_Deutsche_Bank!C7/1000000000 -> 13.064 | C7: =C32*C35 -> 7.1213337
A8: Non-Interest Income (Fees) | B8: =B9-B7 -> 16.983 | C8: =B8*(1+Assumptions!D13) -> 17.32266
A9: Total Revenue | B9: =income_Deutsche_Bank!C36/1000000000 -> 30.047 | C9: =C7+C8 -> 24.443994
A10: Operating Expense (SG&A + Other NIE) | B10: =(income_Deutsche_Bank!C31+income_Deutsche_Bank!C40)/1000000000 -> 18.02 | C10: =B10*(1+Assumptions!D12) -> 18.3804
A11: Pretax Income | B11: =income_Deutsche_Bank!C25/1000000000 -> 5.291 | C11: =C9-C10 -> 6.0635937
A12: Tax Provision (held at FY24 effective 33.8%) | B12: =income_Deutsche_Bank!C24/1000000000 -> 1.786 | C12: =C11*B21 -> 2.0467924
A13: Net Income | B13: =income_Deutsche_Bank!C20/1000000000 -> 3.366 | C13: =C11-C12 -> 4.0168014
A15: Balance Sheet
A16: Total Assets | B16: =balance_Deutsche_Bank!C40/1000000000 -> 1387.177 | C16: =C35 -> 1387.177
A17: Common Stock Equity | B17: =balance_Deutsche_Bank!C10/1000000000 -> 77.826 | C17: =B17+C13 -> 81.842801
A19: Key Ratios
A20: NIM (NII / Total Assets) | B20: =B7/B16 -> 0.0094176879 | C20: =C7/C16 -> 0.0051336879
A21: Effective Tax Rate | B21: =B12/B11 -> 0.33755434 | C21: =B21 -> 0.33755434
A22: ROE (Net Income / Equity) | B22: =B13/B17 -> 0.043250328 | C22: =C13/((B17+C17)/2) -> 0.050314167
A23: Cost-to-Income | B23: =B10/B9 -> 0.59972709 | C23: =C10/C9 -> 0.75193932
A25: FY25E Drivers
A26: Applicable CB rate (ECB) | C26: =Assumptions!E6 -> 0.0225
A27: FY24 CB rate | C27: =Assumptions!F6 -> 0.0315
A28: Δ Rate | C28: =C26-C27 -> -0.009
A29: Deposit Beta | C29: =Assumptions!D10 -> 0.32
A30: Repricing Lag | C30: =Assumptions!D11 -> 0.7
A31: NIM change = ΔRate × (1 − β) × Lag | C31: =C28*(1-C29)*C30 -> -0.004284
A32: NIM FY25E | B32: =B20 -> 0.0094176879 | C32: =B20+C31 -> 0.0051336879
A34: FY25E P&L
A35: Total Assets (held flat) | C35: =B16 -> 1387.177

Sheet Sensitivity
A1: FY2025E ROE Sensitivity - Rate Change vs Deposit Beta
A2: Base = FY2024 actuals. NIM FY25E = NIM FY24 + ΔRate×(1−β)×Lag. Fees & OpEx held flat; tax per each bank's rule.
A4: Barclays (BoE, Lag 65%, Tax 22%)
A5: ΔRate \ β | B5: 0.2 | C5: 0.3 | D5: 0.4 | E5: 0.5 | F5: 0.6 | G5: 0.7 | H5: 0.8
A6: -0.005 | B6: =(((Calc_Barclays!$B$20+$A6*(1-B$5)*Assumptions!$B$11)*Calc_Barclays!$B$16+Calc_Barclays!$B$8*(1+Assumptions!$B$13)-Calc_Barclays!$B$10*(1+Assumptions!$B$12))*(1-Assumptions!$B$14))/(Calc_Barclays!$B$17+(((Calc_Barclays!$B$20+$A6*(1-B$5)*Assumptions!$B$11)*Calc_Barclays!$B$16+Calc_Barclays!$B$8*(1+Assumptions!$B$13)-Calc_Barclays!$B$10*(1+Assumptions!$B$12))*(1-Assumptions!$B$14))/2) -> 0.065804216 | C6: =(((Calc_Barclays!$B$20+$A6*(1-C$5)*Assumptions!$B$11)*Calc_Barclays!$B$16+Calc_Barclays!$B$8*(1+Assumptions!$B$13)-Calc_Barclays!$B$10*(1+Assumptions!$B$12))*(1-Assumptions!$B$14))/(Calc_Barclays!$B$17+(((Calc_Barclays!$B$20+$A6*(1-C$5)*Assumptions!$B$11)*Calc_Barclays!$B$16+Calc_Barclays!$B$8*(1+Assumptions!$B$13)-Calc_Barclays!$B$10*(1+Assumptions!$B$12))*(1-Assumptions!$B$14))/2) -> 0.0708031 | D6: =(((Calc_Barclays!$B$20+$A6*(1-D$5)*Assumptions!$B$11)*Calc_Barclays!$B$16+Calc_Barclays!$B$8*(1+Assumptions!$B$13)-Calc_Barclays!$B$10*(1+Assumptions!$B$12))*(1-Assumptions!$B$14))/(Calc_Barclays!$B$17+(((Calc_Barclays!$B$20+$A6*(1-D$5)*Assumptions!$B$11)*Calc_Barclays!$B$16+Calc_Barclays!$B$8*(1+Assumptions!$B$13)-Calc_Barclays!$B$10*(1+Assumptions!$B$12))*(1-Assumptions!$B$14))/2) -> 0.075776211 | E6: =(((Calc_Barclays!$B$20+$A6*(1-E$5)*Assumptions!$B$11)*Calc_Barclays!$B$16+Calc_Barclays!$B$8*(1+Assumptions!$B$13)-Calc_Barclays!$B$10*(1+Assumptions!$B$12))*(1-Assumptions!$B$14))/(Calc_Barclays!$B$17+(((Calc_Barclays!$B$20+$A6*(1-E$5)*Assumptions!$B$11)*Calc_Barclays!$B$16+Calc_Barclays!$B$8*(1+Assumptions!$B$13)-Calc_Barclays!$B$10*(1+Assumptions!$B$12))*(1-Assumptions!$B$14))/2) -> 0.08072375 | F6: =(((Calc_Barclays!$B$20+$A6*(1-F$5)*Assumptions!$B$11)*Calc_Barclays!$B$16+Calc_Barclays!$B$8*(1+Assumptions!$B$13)-Calc_Barclays!$B$10*(1+Assumptions!$B$12))*(1-Assumptions!$B$14))/(Calc_Barclays!$B$17+(((Calc_Barclays!$B$20+$A6*(1-F$5)*Assumptions!$B$11)*Calc_Barclays!$B$16+Calc_Barclays!$B$8*(1+Assumptions!$B$13)-Calc_Barclays!$B$10*(1+Assumptions!$B$12))*(1-Assumptions!$B$14))/2) -> 0.085645911 | G6: =(((Calc_Barclays!$B$20+$A6*(1-G$5)*Assumptions!$B$11)*Calc_Barclays!$B$16+Calc_Barclays!$B$8*(1+Assumptions!$B$13)-Calc_Barclays!$B$10*(1+Assumptions!$B$12))*(1-Assumptions!$B$14))/(Calc_Barclays!$B$17+(((Calc_Barclays!$B$20+$A6*(1-G$5)*Assumptions!$B$11)*Calc_Barclays!$B$16+Calc_Barclays!$B$8*(1+Assumptions!$B$13)-Calc_Barclays!$B$10*(1+Assumptions!$B$12))*(1-Assumptions!$B$14))/2) -> 0.09054289 | H6: =(((Calc_Barclays!$B$20+$A6*(1-H$5)*Assumptions!$B$11)*Calc_Barclays!$B$16+Calc_Barclays!$B$8*(1+Assumptions!$B$13)-Calc_Barclays!$B$10*(1+Assumptions!$B$12))*(1-Assumptions!$B$14))/(Calc_Barclays!$B$17+(((Calc_Barclays!$B$20+$A6*(1-H$5)*Assumptions!$B$11)*Calc_Barclays!$B$16+Calc_Barclays!$B$8*(1+Assumptions!$B$13)-Calc_Barclays!$B$10*(1+Assumptions!$B$12))*(1-Assumptions!$B$14))/2) -> 0.09541488
A7: -0.0025 | B7: =(((Calc_Barclays!$B$20+$A7*(1-B$5)*Assumptions!$B$11)*Calc_Barclays!$B$16+Calc_Barclays!$B$8*(1+Assumptions!$B$13)-Calc_Barclays!$B$10*(1+Assumptions!$B$12))*(1-Assumptions!$B$14))/(Calc_Barclays!$B$17+(((Calc_Barclays!$B$20+$A7*(1-B$5)*Assumptions!$B$11)*Calc_Barclays!$B$16+Calc_Barclays!$B$8*(1+Assumptions!$B$13)-Calc_Barclays!$B$10*(1+Assumptions!$B$12))*(1-Assumptions!$B$14))/2) -> 0.085645911 | C7: =(((Calc_Barclays!$B$20+$A7*(1-C$5)*Assumptions!$B$11)*Calc_Barclays!$B$16+Calc_Barclays!$B$8*(1+Assumptions!$B$13)-Calc_Barclays!$B$10*(1+Assumptions!$B$12))*(1-Assumptions!$B$14))/(Calc_Barclays!$B$17+(((Calc_Barclays!$B$20+$A7*(1-C$5)*Assumptions!$B$11)*Calc_Barclays!$B$16+Calc_Barclays!$B$8*(1+Assumptions!$B$13)-Calc_Barclays!$B$10*(1+Assumptions!$B$12))*(1-Assumptions!$B$14))/2) -> 0.088097536 | D7: =(((Calc_Barclays!$B$20+$A7*(1-D$5)*Assumptions!$B$11)*Calc_Barclays!$B$16+Calc_Barclays!$B$8*(1+Assumptions!$B$13)-Calc_Barclays!$B$10*(1+Assumptions!$B$12))*(1-Assumptions!$B$14))/(Calc_Barclays!$B$17+(((Calc_Barclays!$B$20+$A7*(1-D$5)*Assumptions!$B$11)*Calc_Barclays!$B$16+Calc_Barclays!$B$8*(1+Assumptions!$B$13)-Calc_Barclays!$B$10*(1+Assumptions!$B$12))*(1-Assumptions!$B$14))/2) -> 0.09054289 | E7: =(((Calc_Barclays!$B$20+$A7*(1-E$5)*Assumptions!$B$11)*Calc_Barclays!$B$16+Calc_Barclays!$B$8*(1+Assumptions!$B$13)-Calc_Barclays!$B$10*(1+Assumptions!$B$12))*(1-Assumptions!$B$14))/(Calc_Barclays!$B$17+(((Calc_Barclays!$B$20+$A7*(1-E$5)*Assumptions!$B$11)*Calc_Barclays!$B$16+Calc_Barclays!$B$8*(1+Assumptions!$B$13)-Calc_Barclays!$B$10*(1+Assumptions!$B$12))*(1-Assumptions!$B$14))/2) -> 0.092981997 | F7: =(((Calc_Barclays!$B$20+$A7*(1-F$5)*Assumptions!$B$11)*Calc_Barclays!$B$16+Calc_Barclays!$B$8*(1+Assumptions!$B$13)-Calc_Barclays!$B$10*(1+Assumptions!$B$12))*(1-Assumptions!$B$14))/(Calc_Barclays!$B$17+(((Calc_Barclays!$B$20+$A7*(1-F$5)*Assumptions!$B$11)*Calc_Barclays!$B$16+Calc_Barclays!$B$8*(1+Assumptions!$B$13)-Calc_Barclays!$B$10*(1+Assumptions!$B$12))*(1-Assumptions!$B$14))/2) -> 0.09541488 | G7: =(((Calc_Barclays!$B$20+$A7*(1-G$5)*Assumptions!$B$11)*Calc_Barclays!$B$16+Calc_Barclays!$B$8*(1+Assumptions!$B$13)-Calc_Barclays!$B$10*(1+Assumptions!$B$12))*(1-Assumptions!$B$14))/(Calc_Barclays!$B$17+(((Calc_Barclays!$B$20+$A7*(1-G$5)*Assumptions!$B$11)*Calc_Barclays!$B$16+Calc_Barclays!$B$8*(1+Assumptions!$B$13)-Calc_Barclays!$B$10*(1+Assumptions!$B$12))*(1-Assumptions!$B$14))/2) -> 0.097841564 | H7: =(((Calc_Barclays!$B$20+$A7*(1-H$5)*Assumptions!$B$11)*Calc_Barclays!$B$16+Calc_Barclays!$B$8*(1+Assumptions!$B$13)-Calc_Barclays!$B$10*(1+Assumptions!$B$12))*(1-Assumptions!$B$14))/(Calc_Barclays!$B$17+(((Calc_Barclays!$B$20+$A7*(1-H$5)*Assumptions!$B$11)*Calc_Barclays!$B$16+Calc_Barclays!$B$8*(1+Assumptions!$B$13)-Calc_Barclays!$B$10*(1+Assumptions!$B$12))*(1-Assumptions!$B$14))/2) -> 0.10026207
A8: 0 | B8: =(((Calc_Barclays!$B$20+$A8*(1-B$5)*Assumptions!$B$11)*Calc_Barclays!$B$16+Calc_Barclays!$B$8*(1+Assumptions!$B$13)-Calc_Barclays!$B$10*(1+Assumptions!$B$12))*(1-Assumptions!$B$14))/(Calc_Barclays!$B$17+(((Calc_Barclays!$B$20+$A8*(1-B$5)*Assumptions!$B$11)*Calc_Barclays!$B$16+Calc_Barclays!$B$8*(1+Assumptions!$B$13)-Calc_Barclays!$B$10*(1+Assumptions!$B$12))*(1-Assumptions!$B$14))/2) -> 0.10508465 | C8: =(((Calc_Barclays!$B$20+$A8*(1-C$5)*Assumptions!$B$11)*Calc_Barclays!$B$16+Calc_Barclays!$B$8*(1+Assumptions!$B$13)-Calc_Barclays!$B$10*(1+Assumptions!$B$12))*(1-Assumptions!$B$14))/(Calc_Barclays!$B$17+(((Calc_Barclays!$B$20+$A8*(1-C$5)*Assumptions!$B$11)*Calc_Barclays!$B$16+Calc_Barclays!$B$8*(1+Assumptions!$B$13)-Calc_Barclays!$B$10*(1+Assumptions!$B$12))*(1-Assumptions!$B$14))/2) -> 0.10508465 | D8: =(((Calc_Barclays!$B$20+$A8*(1-D$5)*Assumptions!$B$11)*Calc_Barclays!$B$16+Calc_Barclays!$B$8*(1+Assumptions!$B$13)-Calc_Barclays!$B$10*(1+Assumptions!$B$12))*(1-Assumptions!$B$14))/(Calc_Barclays!$B$17+(((Calc_Barclays!$B$20+$A8*(1-D$5)*Assumptions!$B$11)*Calc_Barclays!$B$16+Calc_Barclays!$B$8*(1+Assumptions!$B$13)-Calc_Barclays!$B$10*(1+Assumptions!$B$12))*(1-Assumptions!$B$14))/2) -> 0.10508465 | E8: =(((Calc_Barclays!$B$20+$A8*(1-E$5)*Assumptions!$B$11)*Calc_Barclays!$B$16+Calc_Barclays!$B$8*(1+Assumptions!$B$13)-Calc_Barclays!$B$10*(1+Assumptions!$B$12))*(1-Assumptions!$B$14))/(Calc_Barclays!$B$17+(((Calc_Barclays!$B$20+$A8*(1-E$5)*Assumptions!$B$11)*Calc_Barclays!$B$16+Calc_Barclays!$B$8*(1+Assumptions!$B$13)-Calc_Barclays!$B$10*(1+Assumptions!$B$12))*(1-Assumptions!$B$14))/2) -> 0.10508465 | F8: =(((Calc_Barclays!$B$20+$A8*(1-F$5)*Assumptions!$B$11)*Calc_Barclays!$B$16+Calc_Barclays!$B$8*(1+Assumptions!$B$13)-Calc_Barclays!$B$10*(1+Assumptions!$B$12))*(1-Assumptions!$B$14))/(Calc_Barclays!$B$17+(((Calc_Barclays!$B$20+$A8*(1-F$5)*Assumptions!$B$11)*Calc_Barclays!$B$16+Calc_Barclays!$B$8*(1+Assumptions!$B$13)-Calc_Barclays!$B$10*(1+Assumptions!$B$12))*(1-Assumptions!$B$14))/2) -> 0.10508465 | G8: =(((Calc_Barclays!$B$20+$A8*(1-G$5)*Assumptions!$B$11)*Calc_Barclays!$B$16+Calc_Barclays!$B$8*(1+Assumptions!$B$13)-Calc_Barclays!$B$10*(1+Assumptions!$B$12))*(1-Assumptions!$B$14))/(Calc_Barclays!$B$17+(((Calc_Barclays!$B$20+$A8*(1-G$5)*Assumptions!$B$11)*Calc_Barclays!$B$16+Calc_Barclays!$B$8*(1+Assumptions!$B$13)-Calc_Barclays!$B$10*(1+Assumptions!$B$12))*(1-Assumptions!$B$14))/2) -> 0.10508465 | H8: =(((Calc_Barclays!$B$20+$A8*(1-H$5)*Assumptions!$B$11)*Calc_Barclays!$B$16+Calc_Barclays!$B$8*(1+Assumptions!$B$13)-Calc_Barclays!$B$10*(1+Assumptions!$B$12))*(1-Assumptions!$B$14))/(Calc_Barclays!$B$17+(((Calc_Barclays!$B$20+$A8*(1-H$5)*Assumptions!$B$11)*Calc_Barclays!$B$16+Calc_Barclays!$B$8*(1+Assumptions!$B$13)-Calc_Barclays!$B$10*(1+Assumptions!$B$12))*(1-Assumptions!$B$14))/2) -> 0.10508465
A9: 0.0025 | B9: =(((Calc_Barclays!$B$20+$A9*(1-B$5)*Assumptions!$B$11)*Calc_Barclays!$B$16+Calc_Barclays!$B$8*(1+Assumptions!$B$13)-Calc_Barclays!$B$10*(1+Assumptions!$B$12))*(1-Assumptions!$B$14))/(Calc_Barclays!$B$17+(((Calc_Barclays!$B$20+$A9*(1-B$5)*Assumptions!$B$11)*Calc_Barclays!$B$16+Calc_Barclays!$B$8*(1+Assumptions!$B$13)-Calc_Barclays!$B$10*(1+Assumptions!$B$12))*(1-Assumptions!$B$14))/2) -> 0.12413259 | C9: =(((Calc_Barclays!$B$20+$A9*(1-C$5)*Assumptions!$B$11)*Calc_Barclays!$B$16+Calc_Barclays!$B$8*(1+Assumptions!$B$13)-Calc_Barclays!$B$10*(1+Assumptions!$B$12))*(1-Assumptions!$B$14))/(Calc_Barclays!$B$17+(((Calc_Barclays!$B$20+$A9*(1-C$5)*Assumptions!$B$11)*Calc_Barclays!$B$16+Calc_Barclays!$B$8*(1+Assumptions!$B$13)-Calc_Barclays!$B$10*(1+Assumptions!$B$12))*(1-Assumptions!$B$14))/2) -> 0.12177257 | D9: =(((Calc_Barclays!$B$20+$A9*(1-D$5)*Assumptions!$B$11)*Calc_Barclays!$B$16+Calc_Barclays!$B$8*(1+Assumptions!$B$13)-Calc_Barclays!$B$10*(1+Assumptions!$B$12))*(1-Assumptions!$B$14))/(Calc_Barclays!$B$17+(((Calc_Barclays!$B$20+$A9*(1-D$5)*Assumptions!$B$11)*Calc_Barclays!$B$16+Calc_Barclays!$B$8*(1+Assumptions!$B$13)-Calc_Barclays!$B$10*(1+Assumptions!$B$12))*(1-Assumptions!$B$14))/2) -> 0.1194066 | E9: =(((Calc_Barclays!$B$20+$A9*(1-E$5)*Assumptions!$B$11)*Calc_Barclays!$B$16+Calc_Barclays!$B$8*(1+Assumptions!$B$13)-Calc_Barclays!$B$10*(1+Assumptions!$B$12))*(1-Assumptions!$B$14))/(Calc_Barclays!$B$17+(((Calc_Barclays!$B$20+$A9*(1-E$5)*Assumptions!$B$11)*Calc_Barclays!$B$16+Calc_Barclays!$B$8*(1+Assumptions!$B$13)-Calc_Barclays!$B$10*(1+Assumptions!$B$12))*(1-Assumptions!$B$14))/2) -> 0.11703466 | F9: =(((Calc_Barclays!$B$20+$A9*(1-F$5)*Assumptions!$B$11)*Calc_Barclays!$B$16+Calc_Barclays!$B$8*(1+Assumptions!$B$13)-Calc_Barclays!$B$10*(1+Assumptions!$B$12))*(1-Assumptions!$B$14))/(Calc_Barclays!$B$17+(((Calc_Barclays!$B$20+$A9*(1-F$5)*Assumptions!$B$11)*Calc_Barclays!$B$16+Calc_Barclays!$B$8*(1+Assumptions!$B$13)-Calc_Barclays!$B$10*(1+Assumptions!$B$12))*(1-Assumptions!$B$14))/2) -> 0.11465673 | G9: =(((Calc_Barclays!$B$20+$A9*(1-G$5)*Assumptions!$B$11)*Calc_Barclays!$B$16+Calc_Barclays!$B$8*(1+Assumptions!$B$13)-Calc_Barclays!$B$10*(1+Assumptions!$B$12))*(1-Assumptions!$B$14))/(Calc_Barclays!$B$17+(((Calc_Barclays!$B$20+$A9*(1-G$5)*Assumptions!$B$11)*Calc_Barclays!$B$16+Calc_Barclays!$B$8*(1+Assumptions!$B$13)-Calc_Barclays!$B$10*(1+Assumptions!$B$12))*(1-Assumptions!$B$14))/2) -> 0.11227279 | H9: =(((Calc_Barclays!$B$20+$A9*(1-H$5)*Assumptions!$B$11)*Calc_Barclays!$B$16+Calc_Barclays!$B$8*(1+Assumptions!$B$13)-Calc_Barclays!$B$10*(1+Assumptions!$B$12))*(1-Assumptions!$B$14))/(Calc_Barclays!$B$17+(((Calc_Barclays!$B$20+$A9*(1-H$5)*Assumptions!$B$11)*Calc_Barclays!$B$16+Calc_Barclays!$B$8*(1+Assumptions!$B$13)-Calc_Barclays!$B$10*(1+Assumptions!$B$12))*(1-Assumptions!$B$14))/2) -> 0.10988281
A10: 0.005 | B10: =(((Calc_Barclays!$B$20+$A10*(1-B$5)*Assumptions!$B$11)*Calc_Barclays!$B$16+Calc_Barclays!$B$8*(1+Assumptions!$B$13)-Calc_Barclays!$B$10*(1+Assumptions!$B$12))*(1-Assumptions!$B$14))/(Calc_Barclays!$B$17+(((Calc_Barclays!$B$20+$A10*(1-B$5)*Assumptions!$B$11)*Calc_Barclays!$B$16+Calc_Barclays!$B$8*(1+Assumptions!$B$13)-Calc_Barclays!$B$10*(1+Assumptions!$B$12))*(1-Assumptions!$B$14))/2) -> 0.1428014 | C10: =(((Calc_Barclays!$B$20+$A10*(1-C$5)*Assumptions!$B$11)*Calc_Barclays!$B$16+Calc_Barclays!$B$8*(1+Assumptions!$B$13)-Calc_Barclays!$B$10*(1+Assumptions!$B$12))*(1-Assumptions!$B$14))/(Calc_Barclays!$B$17+(((Calc_Barclays!$B$20+$A10*(1-C$5)*Assumptions!$B$11)*Calc_Barclays!$B$16+Calc_Barclays!$B$8*(1+Assumptions!$B$13)-Calc_Barclays!$B$10*(1+Assumptions!$B$12))*(1-Assumptions!$B$14))/2) -> 0.13816912 | D10: =(((Calc_Barclays!$B$20+$A10*(1-D$5)*Assumptions!$B$11)*Calc_Barclays!$B$16+Calc_Barclays!$B$8*(1+Assumptions!$B$13)-Calc_Barclays!$B$10*(1+Assumptions!$B$12))*(1-Assumptions!$B$14))/(Calc_Barclays!$B$17+(((Calc_Barclays!$B$20+$A10*(1-D$5)*Assumptions!$B$11)*Calc_Barclays!$B$16+Calc_Barclays!$B$8*(1+Assumptions!$B$13)-Calc_Barclays!$B$10*(1+Assumptions!$B$12))*(1-Assumptions!$B$14))/2) -> 0.13351368 | E10: =(((Calc_Barclays!$B$20+$A10*(1-E$5)*Assumptions!$B$11)*Calc_Barclays!$B$16+Calc_Barclays!$B$8*(1+Assumptions!$B$13)-Calc_Barclays!$B$10*(1+Assumptions!$B$12))*(1-Assumptions!$B$14))/(Calc_Barclays!$B$17+(((Calc_Barclays!$B$20+$A10*(1-E$5)*Assumptions!$B$11)*Calc_Barclays!$B$16+Calc_Barclays!$B$8*(1+Assumptions!$B$13)-Calc_Barclays!$B$10*(1+Assumptions!$B$12))*(1-Assumptions!$B$14))/2) -> 0.12883489 | F10: =(((Calc_Barclays!$B$20+$A10*(1-F$5)*Assumptions!$B$11)*Calc_Barclays!$B$16+Calc_Barclays!$B$8*(1+Assumptions!$B$13)-Calc_Barclays!$B$10*(1+Assumptions!$B$12))*(1-Assumptions!$B$14))/(Calc_Barclays!$B$17+(((Calc_Barclays!$B$20+$A10*(1-F$5)*Assumptions!$B$11)*Calc_Barclays!$B$16+Calc_Barclays!$B$8*(1+Assumptions!$B$13)-Calc_Barclays!$B$10*(1+Assumptions!$B$12))*(1-Assumptions!$B$14))/2) -> 0.12413259 | G10: =(((Calc_Barclays!$B$20+$A10*(1-G$5)*Assumptions!$B$11)*Calc_Barclays!$B$16+Calc_Barclays!$B$8*(1+Assumptions!$B$13)-Calc_Barclays!$B$10*(1+Assumptions!$B$12))*(1-Assumptions!$B$14))/(Calc_Barclays!$B$17+(((Calc_Barclays!$B$20+$A10*(1-G$5)*Assumptions!$B$11)*Calc_Barclays!$B$16+Calc_Barclays!$B$8*(1+Assumptions!$B$13)-Calc_Barclays!$B$10*(1+Assumptions!$B$12))*(1-Assumptions!$B$14))/2) -> 0.1194066 | H10: =(((Calc_Barclays!$B$20+$A10*(1-H$5)*Assumptions!$B$11)*Calc_Barclays!$B$16+Calc_Barclays!$B$8*(1+Assumptions!$B$13)-Calc_Barclays!$B$10*(1+Assumptions!$B$12))*(1-Assumptions!$B$14))/(Calc_Barclays!$B$17+(((Calc_Barclays!$B$20+$A10*(1-H$5)*Assumptions!$B$11)*Calc_Barclays!$B$16+Calc_Barclays!$B$8*(1+Assumptions!$B$13)-Calc_Barclays!$B$10*(1+Assumptions!$B$12))*(1-Assumptions!$B$14))/2) -> 0.11465673
A13: BNP Paribas (ECB, Lag 60%, Tax 26.5%)
A14: ΔRate \ β | B14: 0.2 | C14: 0.3 | D14: 0.4 | E14: 0.5 | F14: 0.6 | G14: 0.7 | H14: 0.8
A15: -0.005 | B15: =(((Calc_BNP!$B$20+$A15*(1-B$14)*Assumptions!$C$11)*Calc_BNP!$B$16+Calc_BNP!$B$8*(1+Assumptions!$C$13)-Calc_BNP!$B$10*(1+Assumptions!$C$12))*(1-Assumptions!$C$14))/(Calc_BNP!$B$17+(((Calc_BNP!$B$20+$A15*(1-B$14)*Assumptions!$C$11)*Calc_BNP!$B$16+Calc_BNP!$B$8*(1+Assumptions!$C$13)-Calc_BNP!$B$10*(1+Assumptions!$C$12))*(1-Assumptions!$C$14))/2) -> 0.066296243 | C15: =(((Calc_BNP!$B$20+$A15*(1-C$14)*Assumptions!$C$11)*Calc_BNP!$B$16+Calc_BNP!$B$8*(1+Assumptions!$C$13)-Calc_BNP!$B$10*(1+Assumptions!$C$12))*(1-Assumptions!$C$14))/(Calc_BNP!$B$17+(((Calc_BNP!$B$20+$A15*(1-C$14)*Assumptions!$C$11)*Calc_BNP!$B$16+Calc_BNP!$B$8*(1+Assumptions!$C$13)-Calc_BNP!$B$10*(1+Assumptions!$C$12))*(1-Assumptions!$C$14))/2) -> 0.070637648 | D15: =(((Calc_BNP!$B$20+$A15*(1-D$14)*Assumptions!$C$11)*Calc_BNP!$B$16+Calc_BNP!$B$8*(1+Assumptions!$C$13)-Calc_BNP!$B$10*(1+Assumptions!$C$12))*(1-Assumptions!$C$14))/(Calc_BNP!$B$17+(((Calc_BNP!$B$20+$A15*(1-D$14)*Assumptions!$C$11)*Calc_BNP!$B$16+Calc_BNP!$B$8*(1+Assumptions!$C$13)-Calc_BNP!$B$10*(1+Assumptions!$C$12))*(1-Assumptions!$C$14))/2) -> 0.074959603 | E15: =(((Calc_BNP!$B$20+$A15*(1-E$14)*Assumptions!$C$11)*Calc_BNP!$B$16+Calc_BNP!$B$8*(1+Assumptions!$C$13)-Calc_BNP!$B$10*(1+Assumptions!$C$12))*(1-Assumptions!$C$14))/(Calc_BNP!$B$17+(((Calc_BNP!$B$20+$A15*(1-E$14)*Assumptions!$C$11)*Calc_BNP!$B$16+Calc_BNP!$B$8*(1+Assumptions!$C$13)-Calc_BNP!$B$10*(1+Assumptions!$C$12))*(1-Assumptions!$C$14))/2) -> 0.079262237 | F15: =(((Calc_BNP!$B$20+$A15*(1-F$14)*Assumptions!$C$11)*Calc_BNP!$B$16+Calc_BNP!$B$8*(1+Assumptions!$C$13)-Calc_BNP!$B$10*(1+Assumptions!$C$12))*(1-Assumptions!$C$14))/(Calc_BNP!$B$17+(((Calc_BNP!$B$20+$A15*(1-F$14)*Assumptions!$C$11)*Calc_BNP!$B$16+Calc_BNP!$B$8*(1+Assumptions!$C$13)-Calc_BNP!$B$10*(1+Assumptions!$C$12))*(1-Assumptions!$C$14))/2) -> 0.083545681 | G15: =(((Calc_BNP!$B$20+$A15*(1-G$14)*Assumptions!$C$11)*Calc_BNP!$B$16+Calc_BNP!$B$8*(1+Assumptions!$C$13)-Calc_BNP!$B$10*(1+Assumptions!$C$12))*(1-Assumptions!$C$14))/(Calc_BNP!$B$17+(((Calc_BNP!$B$20+$A15*(1-G$14)*Assumptions!$C$11)*Calc_BNP!$B$16+Calc_BNP!$B$8*(1+Assumptions!$C$13)-Calc_BNP!$B$10*(1+Assumptions!$C$12))*(1-Assumptions!$C$14))/2) -> 0.087810063 | H15: =(((Calc_BNP!$B$20+$A15*(1-H$14)*Assumptions!$C$11)*Calc_BNP!$B$16+Calc_BNP!$B$8*(1+Assumptions!$C$13)-Calc_BNP!$B$10*(1+Assumptions!$C$12))*(1-Assumptions!$C$14))/(Calc_BNP!$B$17+(((Calc_BNP!$B$20+$A15*(1-H$14)*Assumptions!$C$11)*Calc_BNP!$B$16+Calc_BNP!$B$8*(1+Assumptions!$C$13)-Calc_BNP!$B$10*(1+Assumptions!$C$12))*(1-Assumptions!$C$14))/2) -> 0.092055509
A16: -0.0025 | B16: =(((Calc_BNP!$B$20+$A16*(1-B$14)*Assumptions!$C$11)*Calc_BNP!$B$16+Calc_BNP!$B$8*(1+Assumptions!$C$13)-Calc_BNP!$B$10*(1+Assumptions!$C$12))*(1-Assumptions!$C$14))/(Calc_BNP!$B$17+(((Calc_BNP!$B$20+$A16*(1-B$14)*Assumptions!$C$11)*Calc_BNP!$B$16+Calc_BNP!$B$8*(1+Assumptions!$C$13)-Calc_BNP!$B$10*(1+Assumptions!$C$12))*(1-Assumptions!$C$14))/2) -> 0.083545681 | C16: =(((Calc_BNP!$B$20+$A16*(1-C$14)*Assumptions!$C$11)*Calc_BNP!$B$16+Calc_BNP!$B$8*(1+Assumptions!$C$13)-Calc_BNP!$B$10*(1+Assumptions!$C$12))*(1-Assumptions!$C$14))/(Calc_BNP!$B$17+(((Calc_BNP!$B$20+$A16*(1-C$14)*Assumptions!$C$11)*Calc_BNP!$B$16+Calc_BNP!$B$8*(1+Assumptions!$C$13)-Calc_BNP!$B$10*(1+Assumptions!$C$12))*(1-Assumptions!$C$14))/2) -> 0.085680247 | D16: =(((Calc_BNP!$B$20+$A16*(1-D$14)*Assumptions!$C$11)*Calc_BNP!$B$16+Calc_BNP!$B$8*(1+Assumptions!$C$13)-Calc_BNP!$B$10*(1+Assumptions!$C$12))*(1-Assumptions!$C$14))/(Calc_BNP!$B$17+(((Calc_BNP!$B$20+$A16*(1-D$14)*Assumptions!$C$11)*Calc_BNP!$B$16+Calc_BNP!$B$8*(1+Assumptions!$C$13)-Calc_BNP!$B$10*(1+Assumptions!$C$12))*(1-Assumptions!$C$14))/2) -> 0.087810063 | E16: =(((Calc_BNP!$B$20+$A16*(1-E$14)*Assumptions!$C$11)*Calc_BNP!$B$16+Calc_BNP!$B$8*(1+Assumptions!$C$13)-Calc_BNP!$B$10*(1+Assumptions!$C$12))*(1-Assumptions!$C$14))/(Calc_BNP!$B$17+(((Calc_BNP!$B$20+$A16*(1-E$14)*Assumptions!$C$11)*Calc_BNP!$B$16+Calc_BNP!$B$8*(1+Assumptions!$C$13)-Calc_BNP!$B$10*(1+Assumptions!$C$12))*(1-Assumptions!$C$14))/2) -> 0.089935145 | F16: =(((Calc_BNP!$B$20+$A16*(1-F$14)*Assumptions!$C$11)*Calc_BNP!$B$16+Calc_BNP!$B$8*(1+Assumptions!$C$13)-Calc_BNP!$B$10*(1+Assumptions!$C$12))*(1-Assumptions!$C$14))/(Calc_BNP!$B$17+(((Calc_BNP!$B$20+$A16*(1-F$14)*Assumptions!$C$11)*Calc_BNP!$B$16+Calc_BNP!$B$8*(1+Assumptions!$C$13)-Calc_BNP!$B$10*(1+Assumptions!$C$12))*(1-Assumptions!$C$14))/2) -> 0.092055509 | G16: =(((Calc_BNP!$B$20+$A16*(1-G$14)*Assumptions!$C$11)*Calc_BNP!$B$16+Calc_BNP!$B$8*(1+Assumptions!$C$13)-Calc_BNP!$B$10*(1+Assumptions!$C$12))*(1-Assumptions!$C$14))/(Calc_BNP!$B$17+(((Calc_BNP!$B$20+$A16*(1-G$14)*Assumptions!$C$11)*Calc_BNP!$B$16+Calc_BNP!$B$8*(1+Assumptions!$C$13)-Calc_BNP!$B$10*(1+Assumptions!$C$12))*(1-Assumptions!$C$14))/2) -> 0.09417117 | H16: =(((Calc_BNP!$B$20+$A16*(1-H$14)*Assumptions!$C$11)*Calc_BNP!$B$16+Calc_BNP!$B$8*(1+Assumptions!$C$13)-Calc_BNP!$B$10*(1+Assumptions!$C$12))*(1-Assumptions!$C$14))/(Calc_BNP!$B$17+(((Calc_BNP!$B$20+$A16*(1-H$14)*Assumptions!$C$11)*Calc_BNP!$B$16+Calc_BNP!$B$8*(1+Assumptions!$C$13)-Calc_BNP!$B$10*(1+Assumptions!$C$12))*(1-Assumptions!$C$14))/2) -> 0.096282145
A17: 0 | B17: =(((Calc_BNP!$B$20+$A17*(1-B$14)*Assumptions!$C$11)*Calc_BNP!$B$16+Calc_BNP!$B$8*(1+Assumptions!$C$13)-Calc_BNP!$B$10*(1+Assumptions!$C$12))*(1-Assumptions!$C$14))/(Calc_BNP!$B$17+(((Calc_BNP!$B$20+$A17*(1-B$14)*Assumptions!$C$11)*Calc_BNP!$B$16+Calc_BNP!$B$8*(1+Assumptions!$C$13)-Calc_BNP!$B$10*(1+Assumptions!$C$12))*(1-Assumptions!$C$14))/2) -> 0.1004901 | C17: =(((Calc_BNP!$B$20+$A17*(1-C$14)*Assumptions!$C$11)*Calc_BNP!$B$16+Calc_BNP!$B$8*(1+Assumptions!$C$13)-Calc_BNP!$B$10*(1+Assumptions!$C$12))*(1-Assumptions!$C$14))/(Calc_BNP!$B$17+(((Calc_BNP!$B$20+$A17*(1-C$14)*Assumptions!$C$11)*Calc_BNP!$B$16+Calc_BNP!$B$8*(1+Assumptions!$C$13)-Calc_BNP!$B$10*(1+Assumptions!$C$12))*(1-Assumptions!$C$14))/2) -> 0.1004901 | D17: =(((Calc_BNP!$B$20+$A17*(1-D$14)*Assumptions!$C$11)*Calc_BNP!$B$16+Calc_BNP!$B$8*(1+Assumptions!$C$13)-Calc_BNP!$B$10*(1+Assumptions!$C$12))*(1-Assumptions!$C$14))/(Calc_BNP!$B$17+(((Calc_BNP!$B$20+$A17*(1-D$14)*Assumptions!$C$11)*Calc_BNP!$B$16+Calc_BNP!$B$8*(1+Assumptions!$C$13)-Calc_BNP!$B$10*(1+Assumptions!$C$12))*(1-Assumptions!$C$14))/2) -> 0.1004901 | E17: =(((Calc_BNP!$B$20+$A17*(1-E$14)*Assumptions!$C$11)*Calc_BNP!$B$16+Calc_BNP!$B$8*(1+Assumptions!$C$13)-Calc_BNP!$B$10*(1+Assumptions!$C$12))*(1-Assumptions!$C$14))/(Calc_BNP!$B$17+(((Calc_BNP!$B$20+$A17*(1-E$14)*Assumptions!$C$11)*Calc_BNP!$B$16+Calc_BNP!$B$8*(1+Assumptions!$C$13)-Calc_BNP!$B$10*(1+Assumptions!$C$12))*(1-Assumptions!$C$14))/2) -> 0.1004901 | F17: =(((Calc_BNP!$B$20+$A17*(1-F$14)*Assumptions!$C$11)*Calc_BNP!$B$16+Calc_BNP!$B$8*(1+Assumptions!$C$13)-Calc_BNP!$B$10*(1+Assumptions!$C$12))*(1-Assumptions!$C$14))/(Calc_BNP!$B$17+(((Calc_BNP!$B$20+$A17*(1-F$14)*Assumptions!$C$11)*Calc_BNP!$B$16+Calc_BNP!$B$8*(1+Assumptions!$C$13)-Calc_BNP!$B$10*(1+Assumptions!$C$12))*(1-Assumptions!$C$14))/2) -> 0.1004901 | G17: =(((Calc_BNP!$B$20+$A17*(1-G$14)*Assumptions!$C$11)*Calc_BNP!$B$16+Calc_BNP!$B$8*(1+Assumptions!$C$13)-Calc_BNP!$B$10*(1+Assumptions!$C$12))*(1-Assumptions!$C$14))/(Calc_BNP!$B$17+(((Calc_BNP!$B$20+$A17*(1-G$14)*Assumptions!$C$11)*Calc_BNP!$B$16+Calc_BNP!$B$8*(1+Assumptions!$C$13)-Calc_BNP!$B$10*(1+Assumptions!$C$12))*(1-Assumptions!$C$14))/2) -> 0.1004901 | H17: =(((Calc_BNP!$B$20+$A17*(1-H$14)*Assumptions!$C$11)*Calc_BNP!$B$16+Calc_BNP!$B$8*(1+Assumptions!$C$13)-Calc_BNP!$B$10*(1+Assumptions!$C$12))*(1-Assumptions!$C$14))/(Calc_BNP!$B$17+(((Calc_BNP!$B$20+$A17*(1-H$14)*Assumptions!$C$11)*Calc_BNP!$B$16+Calc_BNP!$B$8*(1+Assumptions!$C$13)-Calc_BNP!$B$10*(1+Assumptions!$C$12))*(1-Assumptions!$C$14))/2) -> 0.1004901
A18: 0.0025 | B18: =(((Calc_BNP!$B$20+$A18*(1-B$14)*Assumptions!$C$11)*Calc_BNP!$B$16+Calc_BNP!$B$8*(1+Assumptions!$C$13)-Calc_BNP!$B$10*(1+Assumptions!$C$12))*(1-Assumptions!$C$14))/(Calc_BNP!$B$17+(((Calc_BNP!$B$20+$A18*(1-B$14)*Assumptions!$C$11)*Calc_BNP!$B$16+Calc_BNP!$B$8*(1+Assumptions!$C$13)-Calc_BNP!$B$10*(1+Assumptions!$C$12))*(1-Assumptions!$C$14))/2) -> 0.11713751 | C18: =(((Calc_BNP!$B$20+$A18*(1-C$14)*Assumptions!$C$11)*Calc_BNP!$B$16+Calc_BNP!$B$8*(1+Assumptions!$C$13)-Calc_BNP!$B$10*(1+Assumptions!$C$12))*(1-Assumptions!$C$14))/(Calc_BNP!$B$17+(((Calc_BNP!$B$20+$A18*(1-C$14)*Assumptions!$C$11)*Calc_BNP!$B$16+Calc_BNP!$B$8*(1+Assumptions!$C$13)-Calc_BNP!$B$10*(1+Assumptions!$C$12))*(1-Assumptions!$C$14))/2) -> 0.11507256 | D18: =(((Calc_BNP!$B$20+$A18*(1-D$14)*Assumptions!$C$11)*Calc_BNP!$B$16+Calc_BNP!$B$8*(1+Assumptions!$C$13)-Calc_BNP!$B$10*(1+Assumptions!$C$12))*(1-Assumptions!$C$14))/(Calc_BNP!$B$17+(((Calc_BNP!$B$20+$A18*(1-D$14)*Assumptions!$C$11)*Calc_BNP!$B$16+Calc_BNP!$B$8*(1+Assumptions!$C$13)-Calc_BNP!$B$10*(1+Assumptions!$C$12))*(1-Assumptions!$C$14))/2) -> 0.11300307 | E18: =(((Calc_BNP!$B$20+$A18*(1-E$14)*Assumptions!$C$11)*Calc_BNP!$B$16+Calc_BNP!$B$8*(1+Assumptions!$C$13)-Calc_BNP!$B$10*(1+Assumptions!$C$12))*(1-Assumptions!$C$14))/(Calc_BNP!$B$17+(((Calc_BNP!$B$20+$A18*(1-E$14)*Assumptions!$C$11)*Calc_BNP!$B$16+Calc_BNP!$B$8*(1+Assumptions!$C$13)-Calc_BNP!$B$10*(1+Assumptions!$C$12))*(1-Assumptions!$C$14))/2) -> 0.11092904 | F18: =(((Calc_BNP!$B$20+$A18*(1-F$14)*Assumptions!$C$11)*Calc_BNP!$B$16+Calc_BNP!$B$8*(1+Assumptions!$C$13)-Calc_BNP!$B$10*(1+Assumptions!$C$12))*(1-Assumptions!$C$14))/(Calc_BNP!$B$17+(((Calc_BNP!$B$20+$A18*(1-F$14)*Assumptions!$C$11)*Calc_BNP!$B$16+Calc_BNP!$B$8*(1+Assumptions!$C$13)-Calc_BNP!$B$10*(1+Assumptions!$C$12))*(1-Assumptions!$C$14))/2) -> 0.10885044 | G18: =(((Calc_BNP!$B$20+$A18*(1-G$14)*Assumptions!$C$11)*Calc_BNP!$B$16+Calc_BNP!$B$8*(1+Assumptions!$C$13)-Calc_BNP!$B$10*(1+Assumptions!$C$12))*(1-Assumptions!$C$14))/(Calc_BNP!$B$17+(((Calc_BNP!$B$20+$A18*(1-G$14)*Assumptions!$C$11)*Calc_BNP!$B$16+Calc_BNP!$B$8*(1+Assumptions!$C$13)-Calc_BNP!$B$10*(1+Assumptions!$C$12))*(1-Assumptions!$C$14))/2) -> 0.10676726 | H18: =(((Calc_BNP!$B$20+$A18*(1-H$14)*Assumptions!$C$11)*Calc_BNP!$B$16+Calc_BNP!$B$8*(1+Assumptions!$C$13)-Calc_BNP!$B$10*(1+Assumptions!$C$12))*(1-Assumptions!$C$14))/(Calc_BNP!$B$17+(((Calc_BNP!$B$20+$A18*(1-H$14)*Assumptions!$C$11)*Calc_BNP!$B$16+Calc_BNP!$B$8*(1+Assumptions!$C$13)-Calc_BNP!$B$10*(1+Assumptions!$C$12))*(1-Assumptions!$C$14))/2) -> 0.10467949
A19: 0.005 | B19: =(((Calc_BNP!$B$20+$A19*(1-B$14)*Assumptions!$C$11)*Calc_BNP!$B$16+Calc_BNP!$B$8*(1+Assumptions!$C$13)-Calc_BNP!$B$10*(1+Assumptions!$C$12))*(1-Assumptions!$C$14))/(Calc_BNP!$B$17+(((Calc_BNP!$B$20+$A19*(1-B$14)*Assumptions!$C$11)*Calc_BNP!$B$16+Calc_BNP!$B$8*(1+Assumptions!$C$13)-Calc_BNP!$B$10*(1+Assumptions!$C$12))*(1-Assumptions!$C$14))/2) -> 0.13349566 | C19: =(((Calc_BNP!$B$20+$A19*(1-C$14)*Assumptions!$C$11)*Calc_BNP!$B$16+Calc_BNP!$B$8*(1+Assumptions!$C$13)-Calc_BNP!$B$10*(1+Assumptions!$C$12))*(1-Assumptions!$C$14))/(Calc_BNP!$B$17+(((Calc_BNP!$B$20+$A19*(1-C$14)*Assumptions!$C$11)*Calc_BNP!$B$16+Calc_BNP!$B$8*(1+Assumptions!$C$13)-Calc_BNP!$B$10*(1+Assumptions!$C$12))*(1-Assumptions!$C$14))/2) -> 0.12943282 | D19: =(((Calc_BNP!$B$20+$A19*(1-D$14)*Assumptions!$C$11)*Calc_BNP!$B$16+Calc_BNP!$B$8*(1+Assumptions!$C$13)-Calc_BNP!$B$10*(1+Assumptions!$C$12))*(1-Assumptions!$C$14))/(Calc_BNP!$B$17+(((Calc_BNP!$B$20+$A19*(1-D$14)*Assumptions!$C$11)*Calc_BNP!$B$16+Calc_BNP!$B$8*(1+Assumptions!$C$13)-Calc_BNP!$B$10*(1+Assumptions!$C$12))*(1-Assumptions!$C$14))/2) -> 0.12535227 | E19: =(((Calc_BNP!$B$20+$A19*(1-E$14)*Assumptions!$C$11)*Calc_BNP!$B$16+Calc_BNP!$B$8*(1+Assumptions!$C$13)-Calc_BNP!$B$10*(1+Assumptions!$C$12))*(1-Assumptions!$C$14))/(Calc_BNP!$B$17+(((Calc_BNP!$B$20+$A19*(1-E$14)*Assumptions!$C$11)*Calc_BNP!$B$16+Calc_BNP!$B$8*(1+Assumptions!$C$13)-Calc_BNP!$B$10*(1+Assumptions!$C$12))*(1-Assumptions!$C$14))/2) -> 0.12125387 | F19: =(((Calc_BNP!$B$20+$A19*(1-F$14)*Assumptions!$C$11)*Calc_BNP!$B$16+Calc_BNP!$B$8*(1+Assumptions!$C$13)-Calc_BNP!$B$10*(1+Assumptions!$C$12))*(1-Assumptions!$C$14))/(Calc_BNP!$B$17+(((Calc_BNP!$B$20+$A19*(1-F$14)*Assumptions!$C$11)*Calc_BNP!$B$16+Calc_BNP!$B$8*(1+Assumptions!$C$13)-Calc_BNP!$B$10*(1+Assumptions!$C$12))*(1-Assumptions!$C$14))/2) -> 0.11713751 | G19: =(((Calc_BNP!$B$20+$A19*(1-G$14)*Assumptions!$C$11)*Calc_BNP!$B$16+Calc_BNP!$B$8*(1+Assumptions!$C$13)-Calc_BNP!$B$10*(1+Assumptions!$C$12))*(1-Assumptions!$C$14))/(Calc_BNP!$B$17+(((Calc_BNP!$B$20+$A19*(1-G$14)*Assumptions!$C$11)*Calc_BNP!$B$16+Calc_BNP!$B$8*(1+Assumptions!$C$13)-Calc_BNP!$B$10*(1+Assumptions!$C$12))*(1-Assumptions!$C$14))/2) -> 0.11300307 | H19: =(((Calc_BNP!$B$20+$A19*(1-H$14)*Assumptions!$C$11)*Calc_BNP!$B$16+Calc_BNP!$B$8*(1+Assumptions!$C$13)-Calc_BNP!$B$10*(1+Assumptions!$C$12))*(1-Assumptions!$C$14))/(Calc_BNP!$B$17+(((Calc_BNP!$B$20+$A19*(1-H$14)*Assumptions!$C$11)*Calc_BNP!$B$16+Calc_BNP!$B$8*(1+Assumptions!$C$13)-Calc_BNP!$B$10*(1+Assumptions!$C$12))*(1-Assumptions!$C$14))/2) -> 0.10885044
A22: Deutsche Bank (ECB, Lag 70%, Tax 33.8% effective)
A23: ΔRate \ β | B23: 0.2 | C23: 0.3 | D23: 0.4 | E23: 0.5 | F23: 0.6 | G23: 0.7 | H23: 0.8
A24: -0.005 | B24: =(((Calc_Deutsche!$B$20+$A24*(1-B$23)*Assumptions!$D$11)*Calc_Deutsche!$B$16+Calc_Deutsche!$B$8*(1+Assumptions!$D$13)-Calc_Deutsche!$B$10*(1+Assumptions!$D$12))*(1-Calc_Deutsche!$B$21))/(Calc_Deutsche!$B$17+(((Calc_Deutsche!$B$20+$A24*(1-B$23)*Assumptions!$D$11)*Calc_Deutsche!$B$16+Calc_Deutsche!$B$8*(1+Assumptions!$D$13)-Calc_Deutsche!$B$10*(1+Assumptions!$D$12))*(1-Calc_Deutsche!$B$21))/2) -> 0.066824931 | C24: =(((Calc_Deutsche!$B$20+$A24*(1-C$23)*Assumptions!$D$11)*Calc_Deutsche!$B$16+Calc_Deutsche!$B$8*(1+Assumptions!$D$13)-Calc_Deutsche!$B$10*(1+Assumptions!$D$12))*(1-Calc_Deutsche!$B$21))/(Calc_Deutsche!$B$17+(((Calc_Deutsche!$B$20+$A24*(1-C$23)*Assumptions!$D$11)*Calc_Deutsche!$B$16+Calc_Deutsche!$B$8*(1+Assumptions!$D$13)-Calc_Deutsche!$B$10*(1+Assumptions!$D$12))*(1-Calc_Deutsche!$B$21))/2) -> 0.070678306 | D24: =(((Calc_Deutsche!$B$20+$A24*(1-D$23)*Assumptions!$D$11)*Calc_Deutsche!$B$16+Calc_Deutsche!$B$8*(1+Assumptions!$D$13)-Calc_Deutsche!$B$10*(1+Assumptions!$D$12))*(1-Calc_Deutsche!$B$21))/(Calc_Deutsche!$B$17+(((Calc_Deutsche!$B$20+$A24*(1-D$23)*Assumptions!$D$11)*Calc_Deutsche!$B$16+Calc_Deutsche!$B$8*(1+Assumptions!$D$13)-Calc_Deutsche!$B$10*(1+Assumptions!$D$12))*(1-Calc_Deutsche!$B$21))/2) -> 0.07451635 | E24: =(((Calc_Deutsche!$B$20+$A24*(1-E$23)*Assumptions!$D$11)*Calc_Deutsche!$B$16+Calc_Deutsche!$B$8*(1+Assumptions!$D$13)-Calc_Deutsche!$B$10*(1+Assumptions!$D$12))*(1-Calc_Deutsche!$B$21))/(Calc_Deutsche!$B$17+(((Calc_Deutsche!$B$20+$A24*(1-E$23)*Assumptions!$D$11)*Calc_Deutsche!$B$16+Calc_Deutsche!$B$8*(1+Assumptions!$D$13)-Calc_Deutsche!$B$10*(1+Assumptions!$D$12))*(1-Calc_Deutsche!$B$21))/2) -> 0.078339154 | F24: =(((Calc_Deutsche!$B$20+$A24*(1-F$23)*Assumptions!$D$11)*Calc_Deutsche!$B$16+Calc_Deutsche!$B$8*(1+Assumptions!$D$13)-Calc_Deutsche!$B$10*(1+Assumptions!$D$12))*(1-Calc_Deutsche!$B$21))/(Calc_Deutsche!$B$17+(((Calc_Deutsche!$B$20+$A24*(1-F$23)*Assumptions!$D$11)*Calc_Deutsche!$B$16+Calc_Deutsche!$B$8*(1+Assumptions!$D$13)-Calc_Deutsche!$B$10*(1+Assumptions!$D$12))*(1-Calc_Deutsche!$B$21))/2) -> 0.082146809 | G24: =(((Calc_Deutsche!$B$20+$A24*(1-G$23)*Assumptions!$D$11)*Calc_Deutsche!$B$16+Calc_Deutsche!$B$8*(1+Assumptions!$D$13)-Calc_Deutsche!$B$10*(1+Assumptions!$D$12))*(1-Calc_Deutsche!$B$21))/(Calc_Deutsche!$B$17+(((Calc_Deutsche!$B$20+$A24*(1-G$23)*Assumptions!$D$11)*Calc_Deutsche!$B$16+Calc_Deutsche!$B$8*(1+Assumptions!$D$13)-Calc_Deutsche!$B$10*(1+Assumptions!$D$12))*(1-Calc_Deutsche!$B$21))/2) -> 0.085939405 | H24: =(((Calc_Deutsche!$B$20+$A24*(1-H$23)*Assumptions!$D$11)*Calc_Deutsche!$B$16+Calc_Deutsche!$B$8*(1+Assumptions!$D$13)-Calc_Deutsche!$B$10*(1+Assumptions!$D$12))*(1-Calc_Deutsche!$B$21))/(Calc_Deutsche!$B$17+(((Calc_Deutsche!$B$20+$A24*(1-H$23)*Assumptions!$D$11)*Calc_Deutsche!$B$16+Calc_Deutsche!$B$8*(1+Assumptions!$D$13)-Calc_Deutsche!$B$10*(1+Assumptions!$D$12))*(1-Calc_Deutsche!$B$21))/2) -> 0.08971703
A25: -0.0025 | B25: =(((Calc_Deutsche!$B$20+$A25*(1-B$23)*Assumptions!$D$11)*Calc_Deutsche!$B$16+Calc_Deutsche!$B$8*(1+Assumptions!$D$13)-Calc_Deutsche!$B$10*(1+Assumptions!$D$12))*(1-Calc_Deutsche!$B$21))/(Calc_Deutsche!$B$17+(((Calc_Deutsche!$B$20+$A25*(1-B$23)*Assumptions!$D$11)*Calc_Deutsche!$B$16+Calc_Deutsche!$B$8*(1+Assumptions!$D$13)-Calc_Deutsche!$B$10*(1+Assumptions!$D$12))*(1-Calc_Deutsche!$B$21))/2) -> 0.082146809 | C25: =(((Calc_Deutsche!$B$20+$A25*(1-C$23)*Assumptions!$D$11)*Calc_Deutsche!$B$16+Calc_Deutsche!$B$8*(1+Assumptions!$D$13)-Calc_Deutsche!$B$10*(1+Assumptions!$D$12))*(1-Calc_Deutsche!$B$21))/(Calc_Deutsche!$B$17+(((Calc_Deutsche!$B$20+$A25*(1-C$23)*Assumptions!$D$11)*Calc_Deutsche!$B$16+Calc_Deutsche!$B$8*(1+Assumptions!$D$13)-Calc_Deutsche!$B$10*(1+Assumptions!$D$12))*(1-Calc_Deutsche!$B$21))/2) -> 0.084044984 | D25: =(((Calc_Deutsche!$B$20+$A25*(1-D$23)*Assumptions!$D$11)*Calc_Deutsche!$B$16+Calc_Deutsche!$B$8*(1+Assumptions!$D$13)-Calc_Deutsche!$B$10*(1+Assumptions!$D$12))*(1-Calc_Deutsche!$B$21))/(Calc_Deutsche!$B$17+(((Calc_Deutsche!$B$20+$A25*(1-D$23)*Assumptions!$D$11)*Calc_Deutsche!$B$16+Calc_Deutsche!$B$8*(1+Assumptions!$D$13)-Calc_Deutsche!$B$10*(1+Assumptions!$D$12))*(1-Calc_Deutsche!$B$21))/2) -> 0.085939405 | E25: =(((Calc_Deutsche!$B$20+$A25*(1-E$23)*Assumptions!$D$11)*Calc_Deutsche!$B$16+Calc_Deutsche!$B$8*(1+Assumptions!$D$13)-Calc_Deutsche!$B$10*(1+Assumptions!$D$12))*(1-Calc_Deutsche!$B$21))/(Calc_Deutsche!$B$17+(((Calc_Deutsche!$B$20+$A25*(1-E$23)*Assumptions!$D$11)*Calc_Deutsche!$B$16+Calc_Deutsche!$B$8*(1+Assumptions!$D$13)-Calc_Deutsche!$B$10*(1+Assumptions!$D$12))*(1-Calc_Deutsche!$B$21))/2) -> 0.087830083 | F25: =(((Calc_Deutsche!$B$20+$A25*(1-F$23)*Assumptions!$D$11)*Calc_Deutsche!$B$16+Calc_Deutsche!$B$8*(1+Assumptions!$D$13)-Calc_Deutsche!$B$10*(1+Assumptions!$D$12))*(1-Calc_Deutsche!$B$21))/(Calc_Deutsche!$B$17+(((Calc_Deutsche!$B$20+$A25*(1-F$23)*Assumptions!$D$11)*Calc_Deutsche!$B$16+Calc_Deutsche!$B$8*(1+Assumptions!$D$13)-Calc_Deutsche!$B$10*(1+Assumptions!$D$12))*(1-Calc_Deutsche!$B$21))/2) -> 0.08971703 | G25: =(((Calc_Deutsche!$B$20+$A25*(1-G$23)*Assumptions!$D$11)*Calc_Deutsche!$B$16+Calc_Deutsche!$B$8*(1+Assumptions!$D$13)-Calc_Deutsche!$B$10*(1+Assumptions!$D$12))*(1-Calc_Deutsche!$B$21))/(Calc_Deutsche!$B$17+(((Calc_Deutsche!$B$20+$A25*(1-G$23)*Assumptions!$D$11)*Calc_Deutsche!$B$16+Calc_Deutsche!$B$8*(1+Assumptions!$D$13)-Calc_Deutsche!$B$10*(1+Assumptions!$D$12))*(1-Calc_Deutsche!$B$21))/2) -> 0.091600257 | H25: =(((Calc_Deutsche!$B$20+$A25*(1-H$23)*Assumptions!$D$11)*Calc_Deutsche!$B$16+Calc_Deutsche!$B$8*(1+Assumptions!$D$13)-Calc_Deutsche!$B$10*(1+Assumptions!$D$12))*(1-Calc_Deutsche!$B$21))/(Calc_Deutsche!$B$17+(((Calc_Deutsche!$B$20+$A25*(1-H$23)*Assumptions!$D$11)*Calc_Deutsche!$B$16+Calc_Deutsche!$B$8*(1+Assumptions!$D$13)-Calc_Deutsche!$B$10*(1+Assumptions!$D$12))*(1-Calc_Deutsche!$B$21))/2) -> 0.093479774
A26: 0 | B26: =(((Calc_Deutsche!$B$20+$A26*(1-B$23)*Assumptions!$D$11)*Calc_Deutsche!$B$16+Calc_Deutsche!$B$8*(1+Assumptions!$D$13)-Calc_Deutsche!$B$10*(1+Assumptions!$D$12))*(1-Calc_Deutsche!$B$21))/(Calc_Deutsche!$B$17+(((Calc_Deutsche!$B$20+$A26*(1-B$23)*Assumptions!$D$11)*Calc_Deutsche!$B$16+Calc_Deutsche!$B$8*(1+Assumptions!$D$13)-Calc_Deutsche!$B$10*(1+Assumptions!$D$12))*(1-Calc_Deutsche!$B$21))/2) -> 0.097227723 | C26: =(((Calc_Deutsche!$B$20+$A26*(1-C$23)*Assumptions!$D$11)*Calc_Deutsche!$B$16+Calc_Deutsche!$B$8*(1+Assumptions!$D$13)-Calc_Deutsche!$B$10*(1+Assumptions!$D$12))*(1-Calc_Deutsche!$B$21))/(Calc_Deutsche!$B$17+(((Calc_Deutsche!$B$20+$A26*(1-C$23)*Assumptions!$D$11)*Calc_Deutsche!$B$16+Calc_Deutsche!$B$8*(1+Assumptions!$D$13)-Calc_Deutsche!$B$10*(1+Assumptions!$D$12))*(1-Calc_Deutsche!$B$21))/2) -> 0.097227723 | D26: =(((Calc_Deutsche!$B$20+$A26*(1-D$23)*Assumptions!$D$11)*Calc_Deutsche!$B$16+Calc_Deutsche!$B$8*(1+Assumptions!$D$13)-Calc_Deutsche!$B$10*(1+Assumptions!$D$12))*(1-Calc_Deutsche!$B$21))/(Calc_Deutsche!$B$17+(((Calc_Deutsche!$B$20+$A26*(1-D$23)*Assumptions!$D$11)*Calc_Deutsche!$B$16+Calc_Deutsche!$B$8*(1+Assumptions!$D$13)-Calc_Deutsche!$B$10*(1+Assumptions!$D$12))*(1-Calc_Deutsche!$B$21))/2) -> 0.097227723 | E26: =(((Calc_Deutsche!$B$20+$A26*(1-E$23)*Assumptions!$D$11)*Calc_Deutsche!$B$16+Calc_Deutsche!$B$8*(1+Assumptions!$D$13)-Calc_Deutsche!$B$10*(1+Assumptions!$D$12))*(1-Calc_Deutsche!$B$21))/(Calc_Deutsche!$B$17+(((Calc_Deutsche!$B$20+$A26*(1-E$23)*Assumptions!$D$11)*Calc_Deutsche!$B$16+Calc_Deutsche!$B$8*(1+Assumptions!$D$13)-Calc_Deutsche!$B$10*(1+Assumptions!$D$12))*(1-Calc_Deutsche!$B$21))/2) -> 0.097227723 | F26: =(((Calc_Deutsche!$B$20+$A26*(1-F$23)*Assumptions!$D$11)*Calc_Deutsche!$B$16+Calc_Deutsche!$B$8*(1+Assumptions!$D$13)-Calc_Deutsche!$B$10*(1+Assumptions!$D$12))*(1-Calc_Deutsche!$B$21))/(Calc_Deutsche!$B$17+(((Calc_Deutsche!$B$20+$A26*(1-F$23)*Assumptions!$D$11)*Calc_Deutsche!$B$16+Calc_Deutsche!$B$8*(1+Assumptions!$D$13)-Calc_Deutsche!$B$10*(1+Assumptions!$D$12))*(1-Calc_Deutsche!$B$21))/2) -> 0.097227723 | G26: =(((Calc_Deutsche!$B$20+$A26*(1-G$23)*Assumptions!$D$11)*Calc_Deutsche!$B$16+Calc_Deutsche!$B$8*(1+Assumptions!$D$13)-Calc_Deutsche!$B$10*(1+Assumptions!$D$12))*(1-Calc_Deutsche!$B$21))/(Calc_Deutsche!$B$17+(((Calc_Deutsche!$B$20+$A26*(1-G$23)*Assumptions!$D$11)*Calc_Deutsche!$B$16+Calc_Deutsche!$B$8*(1+Assumptions!$D$13)-Calc_Deutsche!$B$10*(1+Assumptions!$D$12))*(1-Calc_Deutsche!$B$21))/2) -> 0.097227723 | H26: =(((Calc_Deutsche!$B$20+$A26*(1-H$23)*Assumptions!$D$11)*Calc_Deutsche!$B$16+Calc_Deutsche!$B$8*(1+Assumptions!$D$13)-Calc_Deutsche!$B$10*(1+Assumptions!$D$12))*(1-Calc_Deutsche!$B$21))/(Calc_Deutsche!$B$17+(((Calc_Deutsche!$B$20+$A26*(1-H$23)*Assumptions!$D$11)*Calc_Deutsche!$B$16+Calc_Deutsche!$B$8*(1+Assumptions!$D$13)-Calc_Deutsche!$B$10*(1+Assumptions!$D$12))*(1-Calc_Deutsche!$B$21))/2) -> 0.097227723
A27: 0.0025 | B27: =(((Calc_Deutsche!$B$20+$A27*(1-B$23)*Assumptions!$D$11)*Calc_Deutsche!$B$16+Calc_Deutsche!$B$8*(1+Assumptions!$D$13)-Calc_Deutsche!$B$10*(1+Assumptions!$D$12))*(1-Calc_Deutsche!$B$21))/(Calc_Deutsche!$B$17+(((Calc_Deutsche!$B$20+$A27*(1-B$23)*Assumptions!$D$11)*Calc_Deutsche!$B$16+Calc_Deutsche!$B$8*(1+Assumptions!$D$13)-Calc_Deutsche!$B$10*(1+Assumptions!$D$12))*(1-Calc_Deutsche!$B$21))/2) -> 0.11207331 | C27: =(((Calc_Deutsche!$B$20+$A27*(1-C$23)*Assumptions!$D$11)*Calc_Deutsche!$B$16+Calc_Deutsche!$B$8*(1+Assumptions!$D$13)-Calc_Deutsche!$B$10*(1+Assumptions!$D$12))*(1-Calc_Deutsche!$B$21))/(Calc_Deutsche!$B$17+(((Calc_Deutsche!$B$20+$A27*(1-C$23)*Assumptions!$D$11)*Calc_Deutsche!$B$16+Calc_Deutsche!$B$8*(1+Assumptions!$D$13)-Calc_Deutsche!$B$10*(1+Assumptions!$D$12))*(1-Calc_Deutsche!$B$21))/2) -> 0.11023029 | D27: =(((Calc_Deutsche!$B$20+$A27*(1-D$23)*Assumptions!$D$11)*Calc_Deutsche!$B$16+Calc_Deutsche!$B$8*(1+Assumptions!$D$13)-Calc_Deutsche!$B$10*(1+Assumptions!$D$12))*(1-Calc_Deutsche!$B$21))/(Calc_Deutsche!$B$17+(((Calc_Deutsche!$B$20+$A27*(1-D$23)*Assumptions!$D$11)*Calc_Deutsche!$B$16+Calc_Deutsche!$B$8*(1+Assumptions!$D$13)-Calc_Deutsche!$B$10*(1+Assumptions!$D$12))*(1-Calc_Deutsche!$B$21))/2) -> 0.10838367 | E27: =(((Calc_Deutsche!$B$20+$A27*(1-E$23)*Assumptions!$D$11)*Calc_Deutsche!$B$16+Calc_Deutsche!$B$8*(1+Assumptions!$D$13)-Calc_Deutsche!$B$10*(1+Assumptions!$D$12))*(1-Calc_Deutsche!$B$21))/(Calc_Deutsche!$B$17+(((Calc_Deutsche!$B$20+$A27*(1-E$23)*Assumptions!$D$11)*Calc_Deutsche!$B$16+Calc_Deutsche!$B$8*(1+Assumptions!$D$13)-Calc_Deutsche!$B$10*(1+Assumptions!$D$12))*(1-Calc_Deutsche!$B$21))/2) -> 0.10653344 | F27: =(((Calc_Deutsche!$B$20+$A27*(1-F$23)*Assumptions!$D$11)*Calc_Deutsche!$B$16+Calc_Deutsche!$B$8*(1+Assumptions!$D$13)-Calc_Deutsche!$B$10*(1+Assumptions!$D$12))*(1-Calc_Deutsche!$B$21))/(Calc_Deutsche!$B$17+(((Calc_Deutsche!$B$20+$A27*(1-F$23)*Assumptions!$D$11)*Calc_Deutsche!$B$16+Calc_Deutsche!$B$8*(1+Assumptions!$D$13)-Calc_Deutsche!$B$10*(1+Assumptions!$D$12))*(1-Calc_Deutsche!$B$21))/2) -> 0.10467959 | G27: =(((Calc_Deutsche!$B$20+$A27*(1-G$23)*Assumptions!$D$11)*Calc_Deutsche!$B$16+Calc_Deutsche!$B$8*(1+Assumptions!$D$13)-Calc_Deutsche!$B$10*(1+Assumptions!$D$12))*(1-Calc_Deutsche!$B$21))/(Calc_Deutsche!$B$17+(((Calc_Deutsche!$B$20+$A27*(1-G$23)*Assumptions!$D$11)*Calc_Deutsche!$B$16+Calc_Deutsche!$B$8*(1+Assumptions!$D$13)-Calc_Deutsche!$B$10*(1+Assumptions!$D$12))*(1-Calc_Deutsche!$B$21))/2) -> 0.1028221 | H27: =(((Calc_Deutsche!$B$20+$A27*(1-H$23)*Assumptions!$D$11)*Calc_Deutsche!$B$16+Calc_Deutsche!$B$8*(1+Assumptions!$D$13)-Calc_Deutsche!$B$10*(1+Assumptions!$D$12))*(1-Calc_Deutsche!$B$21))/(Calc_Deutsche!$B$17+(((Calc_Deutsche!$B$20+$A27*(1-H$23)*Assumptions!$D$11)*Calc_Deutsche!$B$16+Calc_Deutsche!$B$8*(1+Assumptions!$D$13)-Calc_Deutsche!$B$10*(1+Assumptions!$D$12))*(1-Calc_Deutsche!$B$21))/2) -> 0.10096097
A28: 0.005 | B28: =(((Calc_Deutsche!$B$20+$A28*(1-B$23)*Assumptions!$D$11)*Calc_Deutsche!$B$16+Calc_Deutsche!$B$8*(1+Assumptions!$D$13)-Calc_Deutsche!$B$10*(1+Assumptions!$D$12))*(1-Calc_Deutsche!$B$21))/(Calc_Deutsche!$B$17+(((Calc_Deutsche!$B$20+$A28*(1-B$23)*Assumptions!$D$11)*Calc_Deutsche!$B$16+Calc_Deutsche!$B$8*(1+Assumptions!$D$13)-Calc_Deutsche!$B$10*(1+Assumptions!$D$12))*(1-Calc_Deutsche!$B$21))/2) -> 0.12668904 | C28: =(((Calc_Deutsche!$B$20+$A28*(1-C$23)*Assumptions!$D$11)*Calc_Deutsche!$B$16+Calc_Deutsche!$B$8*(1+Assumptions!$D$13)-Calc_Deutsche!$B$10*(1+Assumptions!$D$12))*(1-Calc_Deutsche!$B$21))/(Calc_Deutsche!$B$17+(((Calc_Deutsche!$B$20+$A28*(1-C$23)*Assumptions!$D$11)*Calc_Deutsche!$B$16+Calc_Deutsche!$B$8*(1+Assumptions!$D$13)-Calc_Deutsche!$B$10*(1+Assumptions!$D$12))*(1-Calc_Deutsche!$B$21))/2) -> 0.12305636 | D28: =(((Calc_Deutsche!$B$20+$A28*(1-D$23)*Assumptions!$D$11)*Calc_Deutsche!$B$16+Calc_Deutsche!$B$8*(1+Assumptions!$D$13)-Calc_Deutsche!$B$10*(1+Assumptions!$D$12))*(1-Calc_Deutsche!$B$21))/(Calc_Deutsche!$B$17+(((Calc_Deutsche!$B$20+$A28*(1-D$23)*Assumptions!$D$11)*Calc_Deutsche!$B$16+Calc_Deutsche!$B$8*(1+Assumptions!$D$13)-Calc_Deutsche!$B$10*(1+Assumptions!$D$12))*(1-Calc_Deutsche!$B$21))/2) -> 0.11940957 | E28: =(((Calc_Deutsche!$B$20+$A28*(1-E$23)*Assumptions!$D$11)*Calc_Deutsche!$B$16+Calc_Deutsche!$B$8*(1+Assumptions!$D$13)-Calc_Deutsche!$B$10*(1+Assumptions!$D$12))*(1-Calc_Deutsche!$B$21))/(Calc_Deutsche!$B$17+(((Calc_Deutsche!$B$20+$A28*(1-E$23)*Assumptions!$D$11)*Calc_Deutsche!$B$16+Calc_Deutsche!$B$8*(1+Assumptions!$D$13)-Calc_Deutsche!$B$10*(1+Assumptions!$D$12))*(1-Calc_Deutsche!$B$21))/2) -> 0.11574858 | F28: =(((Calc_Deutsche!$B$20+$A28*(1-F$23)*Assumptions!$D$11)*Calc_Deutsche!$B$16+Calc_Deutsche!$B$8*(1+Assumptions!$D$13)-Calc_Deutsche!$B$10*(1+Assumptions!$D$12))*(1-Calc_Deutsche!$B$21))/(Calc_Deutsche!$B$17+(((Calc_Deutsche!$B$20+$A28*(1-F$23)*Assumptions!$D$11)*Calc_Deutsche!$B$16+Calc_Deutsche!$B$8*(1+Assumptions!$D$13)-Calc_Deutsche!$B$10*(1+Assumptions!$D$12))*(1-Calc_Deutsche!$B$21))/2) -> 0.11207331 | G28: =(((Calc_Deutsche!$B$20+$A28*(1-G$23)*Assumptions!$D$11)*Calc_Deutsche!$B$16+Calc_Deutsche!$B$8*(1+Assumptions!$D$13)-Calc_Deutsche!$B$10*(1+Assumptions!$D$12))*(1-Calc_Deutsche!$B$21))/(Calc_Deutsche!$B$17+(((Calc_Deutsche!$B$20+$A28*(1-G$23)*Assumptions!$D$11)*Calc_Deutsche!$B$16+Calc_Deutsche!$B$8*(1+Assumptions!$D$13)-Calc_Deutsche!$B$10*(1+Assumptions!$D$12))*(1-Calc_Deutsche!$B$21))/2) -> 0.10838367 | H28: =(((Calc_Deutsche!$B$20+$A28*(1-H$23)*Assumptions!$D$11)*Calc_Deutsche!$B$16+Calc_Deutsche!$B$8*(1+Assumptions!$D$13)-Calc_Deutsche!$B$10*(1+Assumptions!$D$12))*(1-Calc_Deutsche!$B$21))/(Calc_Deutsche!$B$17+(((Calc_Deutsche!$B$20+$A28*(1-H$23)*Assumptions!$D$11)*Calc_Deutsche!$B$16+Calc_Deutsche!$B$8*(1+Assumptions!$D$13)-Calc_Deutsche!$B$10*(1+Assumptions!$D$12))*(1-Calc_Deutsche!$B$21))/2) -> 0.10467959

Sheet Scenarios
A1: Scenario Comparison - FY2025E by Bank
A2: Bear: −25bps rate change | Base: 0bps | Bull: +25bps. Fees, OpEx, tax, β, lag per Assumptions.
B3: Bear | C3: Base | D3: Bull
A4: ΔRate applied | B4: -0.0025 | C4: 0 | D4: 0.0025
A6: Barclays (GBP, bn)
A7: Net Income | B7: =((Calc_Barclays!$B$20+B$4*(1-Assumptions!$B$10)*Assumptions!$B$11)*Calc_Barclays!$B$16+Calc_Barclays!$B$8*(1+Assumptions!$B$13)-Calc_Barclays!$B$10*(1+Assumptions!$B$12))*(1-Assumptions!$B$14) -> 6.8497218 | C7: =((Calc_Barclays!$B$20+C$4*(1-Assumptions!$B$10)*Assumptions!$B$11)*Calc_Barclays!$B$16+Calc_Barclays!$B$8*(1+Assumptions!$B$13)-Calc_Barclays!$B$10*(1+Assumptions!$B$12))*(1-Assumptions!$B$14) -> 7.965828 | D7: =((Calc_Barclays!$B$20+D$4*(1-Assumptions!$B$10)*Assumptions!$B$11)*Calc_Barclays!$B$16+Calc_Barclays!$B$8*(1+Assumptions!$B$13)-Calc_Barclays!$B$10*(1+Assumptions!$B$12))*(1-Assumptions!$B$14) -> 9.0819342
A8: ROE | B8: =B7/(Calc_Barclays!$B$17+B7/2) -> 0.09103121 | C8: =C7/(Calc_Barclays!$B$17+C7/2) -> 0.10508465 | D8: =D7/(Calc_Barclays!$B$17+D7/2) -> 0.11893269
A9: NIM | B9: =Calc_Barclays!$B$20+B$4*(1-Assumptions!$B$10)*Assumptions!$B$11 -> 0.0075781053 | C9: =Calc_Barclays!$B$20+C$4*(1-Assumptions!$B$10)*Assumptions!$B$11 -> 0.0085206053 | D9: =Calc_Barclays!$B$20+D$4*(1-Assumptions!$B$10)*Assumptions!$B$11 -> 0.0094631053
A10: Cost to Income | B10: =(Calc_Barclays!$B$10*(1+Assumptions!$B$12))/((Calc_Barclays!$B$20+B$4*(1-Assumptions!$B$10)*Assumptions!$B$11)*Calc_Barclays!$B$16+Calc_Barclays!$B$8*(1+Assumptions!$B$13)) -> 0.64964279 | C10: =(Calc_Barclays!$B$10*(1+Assumptions!$B$12))/((Calc_Barclays!$B$20+C$4*(1-Assumptions!$B$10)*Assumptions!$B$11)*Calc_Barclays!$B$16+Calc_Barclays!$B$8*(1+Assumptions!$B$13)) -> 0.61455894 | D10: =(Calc_Barclays!$B$10*(1+Assumptions!$B$12))/((Calc_Barclays!$B$20+D$4*(1-Assumptions!$B$10)*Assumptions!$B$11)*Calc_Barclays!$B$16+Calc_Barclays!$B$8*(1+Assumptions!$B$13)) -> 0.58307033
A12: BNP Paribas (EUR, bn)
A13: Net Income | B13: =((Calc_BNP!$B$20+B$4*(1-Assumptions!$C$10)*Assumptions!$C$11)*Calc_BNP!$B$16+Calc_BNP!$B$8*(1+Assumptions!$C$13)-Calc_BNP!$B$10*(1+Assumptions!$C$12))*(1-Assumptions!$C$14) -> 11.708767 | C13: =((Calc_BNP!$B$20+C$4*(1-Assumptions!$C$10)*Assumptions!$C$11)*Calc_BNP!$B$16+Calc_BNP!$B$8*(1+Assumptions!$C$13)-Calc_BNP!$B$10*(1+Assumptions!$C$12))*(1-Assumptions!$C$14) -> 13.557707 | D13: =((Calc_BNP!$B$20+D$4*(1-Assumptions!$C$10)*Assumptions!$C$11)*Calc_BNP!$B$16+Calc_BNP!$B$8*(1+Assumptions!$C$13)-Calc_BNP!$B$10*(1+Assumptions!$C$12))*(1-Assumptions!$C$14) -> 15.406647
A14: ROE | B14: =B13/(Calc_BNP!$B$17+B13/2) -> 0.087384479 | C14: =C13/(Calc_BNP!$B$17+C13/2) -> 0.1004901 | D14: =D13/(Calc_BNP!$B$17+D13/2) -> 0.11341733
A15: NIM | B15: =Calc_BNP!$B$20+B$4*(1-Assumptions!$C$10)*Assumptions!$C$11 -> 0.0062879904 | C15: =Calc_BNP!$B$20+C$4*(1-Assumptions!$C$10)*Assumptions!$C$11 -> 0.0072179904 | D15: =Calc_BNP!$B$20+D$4*(1-Assumptions!$C$10)*Assumptions!$C$11 -> 0.0081479904
A16: Cost to Income | B16: =(Calc_BNP!$B$10*(1+Assumptions!$C$12))/((Calc_BNP!$B$20+B$4*(1-Assumptions!$C$10)*Assumptions!$C$11)*Calc_BNP!$B$16+Calc_BNP!$B$8*(1+Assumptions!$C$13)) -> 0.7521786 | C16: =(Calc_BNP!$B$10*(1+Assumptions!$C$12))/((Calc_BNP!$B$20+C$4*(1-Assumptions!$C$10)*Assumptions!$C$11)*Calc_BNP!$B$16+Calc_BNP!$B$8*(1+Assumptions!$C$13)) -> 0.72385164 | D16: =(Calc_BNP!$B$10*(1+Assumptions!$C$12))/((Calc_BNP!$B$20+D$4*(1-Assumptions!$C$10)*Assumptions!$C$11)*Calc_BNP!$B$16+Calc_BNP!$B$8*(1+Assumptions!$C$13)) -> 0.69758082
A18: Deutsche Bank (EUR, bn)
A19: Net Income | B19: =((Calc_Deutsche!$B$20+B$4*(1-Assumptions!$D$10)*Assumptions!$D$11)*Calc_Deutsche!$B$16+Calc_Deutsche!$B$8*(1+Assumptions!$D$13)-Calc_Deutsche!$B$10*(1+Assumptions!$D$12))*(1-Calc_Deutsche!$B$21) -> 6.8599689 | C19: =((Calc_Deutsche!$B$20+C$4*(1-Assumptions!$D$10)*Assumptions!$D$11)*Calc_Deutsche!$B$16+Calc_Deutsche!$B$8*(1+Assumptions!$D$13)-Calc_Deutsche!$B$10*(1+Assumptions!$D$12))*(1-Calc_Deutsche!$B$21) -> 7.9534949 | D19: =((Calc_Deutsche!$B$20+D$4*(1-Assumptions!$D$10)*Assumptions!$D$11)*Calc_Deutsche!$B$16+Calc_Deutsche!$B$8*(1+Assumptions!$D$13)-Calc_Deutsche!$B$10*(1+Assumptions!$D$12))*(1-Calc_Deutsche!$B$21) -> 9.0470208
A20: ROE | B20: =B19/(Calc_Deutsche!$B$17+B19/2) -> 0.084424168 | C20: =C19/(Calc_Deutsche!$B$17+C19/2) -> 0.097227723 | D20: =D19/(Calc_Deutsche!$B$17+D19/2) -> 0.10986126
A21: NIM | B21: =Calc_Deutsche!$B$20+B$4*(1-Assumptions!$D$10)*Assumptions!$D$11 -> 0.0082276879 | C21: =Calc_Deutsche!$B$20+C$4*(1-Assumptions!$D$10)*Assumptions!$D$11 -> 0.0094176879 | D21: =Calc_Deutsche!$B$20+D$4*(1-Assumptions!$D$10)*Assumptions!$D$11 -> 0.010607688
A22: Cost to Income | B22: =(Calc_Deutsche!$B$10*(1+Assumptions!$D$12))/((Calc_Deutsche!$B$20+B$4*(1-Assumptions!$D$10)*Assumptions!$D$11)*Calc_Deutsche!$B$16+Calc_Deutsche!$B$8*(1+Assumptions!$D$13)) -> 0.63963153 | C22: =(Calc_Deutsche!$B$10*(1+Assumptions!$D$12))/((Calc_Deutsche!$B$20+C$4*(1-Assumptions!$D$10)*Assumptions!$D$11)*Calc_Deutsche!$B$16+Calc_Deutsche!$B$8*(1+Assumptions!$D$13)) -> 0.60488385 | D22: =(Calc_Deutsche!$B$10*(1+Assumptions!$D$12))/((Calc_Deutsche!$B$20+D$4*(1-Assumptions!$D$10)*Assumptions!$D$11)*Calc_Deutsche!$B$16+Calc_Deutsche!$B$8*(1+Assumptions!$D$13)) -> 0.57371696

Sheet Chartbook
A1: EMEA Banks - Chartbook
A2: Source: Company annual reports, Yahoo Finance (yfinance)
A4: Chart 1 data: FY2025E Net Income by scenario
A5: Bank | B5: Bear | C5: Base | D5: Bull
A6: Barclays | B6: =Scenarios!B7 -> 6.8497218 | C6: =Scenarios!C7 -> 7.965828 | D6: =Scenarios!D7 -> 9.0819342
A7: BNP Paribas | B7: =Scenarios!B13 -> 11.708767 | C7: =Scenarios!C13 -> 13.557707 | D7: =Scenarios!D13 -> 15.406647
A8: Deutsche Bank | B8: =Scenarios!B19 -> 6.8599689 | C8: =Scenarios!C19 -> 7.9534949 | D8: =Scenarios!D19 -> 9.0470208
A10: Chart 2 data: Historical ROE (%)
A11: Year | B11: Barclays | C11: BNP Paribas | D11: Deutsche Bank | E11: 10% Target
A12: 2022 | B12: ='ratios_summary'!D2 -> 8.6804 | C12: ='ratios_summary'!D5 -> 8.1229 | D12: ='ratios_summary'!D8 -> 7.8328 | E12: 10
A13: 2023 | B13: ='ratios_summary'!D3 -> 7.3858 | C13: ='ratios_summary'!D6 -> 8.8693 | D13: ='ratios_summary'!D9 -> 6.5322 | E13: 10
A14: 2024 | B14: ='ratios_summary'!D4 -> 8.7816 | C14: ='ratios_summary'!D7 -> 9.1215 | D14: ='ratios_summary'!D10 -> 4.325 | E14: 10
A16: Chart 3 data: Historical NIM (%)
A17: Year | B17: Barclays | C17: BNP Paribas | D17: Deutsche Bank
A18: 2022 | B18: ='ratios_summary'!C2 -> 0.6984 | C18: ='ratios_summary'!C5 -> 0.7858 | D18: ='ratios_summary'!C8 -> 1.0211
A19: 2023 | B19: ='ratios_summary'!C3 -> 0.8602 | C19: ='ratios_summary'!C6 -> 0.7354 | D19: ='ratios_summary'!C9 -> 1.0365 | F19: Source: Company annual reports, Yahoo Finance (yfinance)
A20: 2024 | B20: ='ratios_summary'!C4 -> 0.8521 | C20: ='ratios_summary'!C7 -> 0.7218 | D20: ='ratios_summary'!C10 -> 0.9418
A22: Chart 4 data: FY2024 Cost-to-Income (%)
A23: Bank | B23: C/I % | C23: 70% Threshold
A24: Barclays | B24: ='ratios_summary'!F4 -> 60.8616 | C24: 70
A25: BNP Paribas | B25: ='ratios_summary'!F7 -> 71.9645 | C25: 70
A26: Deutsche Bank | B26: ='ratios_summary'!F10 -> 59.9727 | C26: 70
F35: Source: Company annual reports, Yahoo Finance (yfinance)
F51: Source: Company annual reports, Yahoo Finance (yfinance)
F67: Source: Company annual reports, Yahoo Finance (yfinance)

Sheet ratios_summary
A1: Bank | B1: Year | C1: NIM (%) | D1: ROE (%) | E1: ROA (%) | F1: Cost to Income (%) | G1: Net Income (bn)
A2: Barclays | B2: 2022 | C2: 0.6984 | D2: 8.6804 | E2: 0.3916 | F2: 60.2574 | G2: 5.928
A3: Barclays | B3: 2023 | C3: 0.8602 | D3: 7.3858 | E3: 0.3559 | F3: 63.3431 | G3: 5.259
A4: Barclays | B4: 2024 | C4: 0.8521 | D4: 8.7816 | E4: 0.4154 | F4: 60.8616 | G4: 6.307
A5: BNP Paribas | B5: 2022 | C5: 0.7858 | D5: 8.1229 | E5: 0.3697 | F5: 72.8726 | G5: 9.848
